<?xml version="1.0"?>
<robot xmlns:xacro="http://www.ros.org/wiki/xacro" name="robot_xacro">
  <xacro:include filename="$(find assignment2)/urdf/robot_model.gazebo" />
  
  <!-- Create body model -->
  <link name="base_link">
    <inertial>
      <mass value="5" />
      <origin rpy="0 0 0" xyz="0 0 0.1" />
      <inertia ixx="0.0395416666667" ixy="0" ixz="0" iyy="0.106208333333" iyz="0" izz="0.106208333333" />
    </inertial>
    <collision name="collision_chassis">
      <geometry>
        <box size="0.5 0.3 0.07" />
      </geometry>
    </collision>
    <visual>
      <origin rpy="0 0 0" xyz="0 0 0" />
      <geometry>
        <box size="0.5 0.3 0.07" />
      </geometry>
    </visual>
  </link>
  <link name="link_front_balance">
    <inertial>
      <mass value="0.2" />
      <origin rpy="0 0 0" xyz="0.08 0 -0.02" />
      <inertia ixx="0.0002" ixy="0" ixz="0" iyy="0.0002" iyz="0" izz="0.0002" />
    </inertial>
    <collision name="front_balance_collision">
      <origin rpy="0 0 0" xyz="0.08 0 -0.02" />
      <geometry>
        <sphere radius="0.05" />
      </geometry>
    </collision>
    <visual name="front_balance_visual">
      <origin rpy="0 0 0" xyz="0.08 0 -0.02" />
      <geometry>
        <sphere radius="0.05" />
      </geometry>
    </visual>
  </link>
  <joint name="joint_front_balance" type="continuous">
    <origin rpy="0 0 0" xyz="0.08 0 -0.02" />
    <child link="link_front_balance" />
    <parent link="base_link" />
    <axis rpy="0 0 0" xyz="1 1 1" />
    <limit effort="10000" velocity="1000" />
    <joint_properties damping="1.0" friction="1.0" />
  </joint>
  <xacro:macro name="link_wheel" params="name">
    <link name="${name}">
      <inertial>
        <mass value="0.2" />
        <origin rpy="0 1.5707 1.5707" xyz="0 0 0" />
        <inertia ixx="0.000526666666667" ixy="0" ixz="0" iyy="0.000526666666667" iyz="0" izz="0.001" />
      </inertial>
      <collision name="${name}_collision">
        <origin rpy="0 1.5707 1.5707" xyz="0 0 0" />
        <geometry>
          <cylinder length="0.04" radius="0.1" />
        </geometry>
      </collision>
      <visual name="${name}_visual">
        <origin rpy="0 1.5707 1.5707" xyz="0 0 0" />
        <geometry>
          <cylinder length="0.04" radius="0.1" />
        </geometry>
      </visual>
    </link>
  </xacro:macro>
  <xacro:macro name="joint_wheel" params="name child origin_xyz">
    <joint name="${name}" type="continuous">
      <origin rpy="0 0 0" xyz="${origin_xyz}" />
      <child link="${child}" />
      <parent link="base_link" />
      <axis rpy="0 0 0" xyz="0 1 0" />
      <limit effort="10000" velocity="1000" />
      <joint_properties damping="1.0" friction="1.0" />
    </joint>
  </xacro:macro>
  <xacro:link_wheel name="link_back_right_wheel" />
  <xacro:link_wheel name="link_back_left_wheel" />
  <xacro:joint_wheel name="joint_back_right_wheel" child="link_back_right_wheel" origin_xyz="-0.05 0.15 0" />
  <xacro:joint_wheel name="joint_back_left_wheel" child="link_back_left_wheel" origin_xyz="-0.05 -0.15 0" />
  
  <!-- Create camera model -->
  <link name="camera_link">
    <inertial>
      <mass value="0.1" />
      <origin rpy="0 0 0" xyz="0 0 0.035" />
      <inertia ixx="1e-4" ixy="0" ixz="0" iyy="1e-4" iyz="0" izz="0.000015" />
    </inertial>
    <collision name="camera_collision">
      <geometry>
        <box size="0.03 0.03 0.1" />
      </geometry>
    </collision>
    <visual>
      <origin rpy="0 0 0" xyz="0 0 0.035" />
      <geometry>
        <box size="0.03 0.03 0.1" />
      </geometry>
    </visual>
  </link>
  <joint name="camera_joint" type="continuous">
    <origin rpy="0 0 0" xyz="0 0 0.035" />
    <child link="camera_link" />
    <parent link="base_link" />
    <axis xyz="0 0 1" />
    <limit effort="10000" velocity="1000" />
    <joint_properties damping="1.0" friction="1.0" />
  </joint>
  
  <!-- Create transmission model -->
  <transmission name="back_left_wheel_transmission">
    <type>transmission_interface/SimpleTransmission</type>
    <joint name="joint_back_left_wheel">
      <hardwareInterface>hardware_interface/EffortJointInterface</hardwareInterface>
    </joint>
    <actuator name="motor1">
      <hardwareInterface>hardware_interface/EffortJointInterface</hardwareInterface>
      <mechanicalInterface>1</mechanicalInterface>
    </actuator>
  </transmission>
  <transmission name="back_right_wheel_transmission">
    <type>transmission_interface/SimpleTransmission</type>
    <joint name="joint_back_right_wheel">
      <hardwareInterface>hardware_interface/EffortJointInterface</hardwareInterface>
    </joint>
    <actuator name="motor2">
      <hardwareInterface>hardware_interface/EffortJointInterface</hardwareInterface>
      <mechanicalInterface>1</mechanicalInterface>
    </actuator>
  </transmission>
  <transmission name="camera_link_transmission">
    <type>transmission_interface/SimpleTransmission</type>
    <joint name="camera_joint">
      <hardwareInterface>hardware_interface/EffortJointInterface</hardwareInterface>
    </joint>
    <actuator name="motor3">
      <hardwareInterface>hardware_interface/EffortJointInterface</hardwareInterface>
      <mechanicalInterface>1</mechanicalInterface>
    </actuator>
  </transmission>
</robot>
